<?xml version="1.0" encoding="UTF-8"?>
<testng-results skipped="0" failed="3" total="6" passed="3">
  <reporter-output>
  </reporter-output>
  <suite name="Suite" duration-ms="56" started-at="2015-11-27T16:56:34Z" finished-at="2015-11-27T16:56:34Z">
    <groups>
    </groups>
    <test name="Test" duration-ms="56" started-at="2015-11-27T16:56:34Z" finished-at="2015-11-27T16:56:34Z">
      <class name="MavenTestCases.TestClass1">
        <test-method status="FAIL" signature="Test1()[pri:0, instance:MavenTestCases.TestClass1@735f7ae5]" name="Test1" duration-ms="1" started-at="2015-11-27T16:56:34Z" finished-at="2015-11-27T16:56:34Z">
          <exception class="java.lang.AssertionError">
            <message>
              <![CDATA[expected:<20> but was:<15>]]>
            </message>
            <full-stacktrace>
              <![CDATA[java.lang.AssertionError: expected:<20> but was:<15>
	at org.testng.Assert.fail(Assert.java:89)
	at org.testng.Assert.failNotEquals(Assert.java:489)
	at org.testng.Assert.assertEquals(Assert.java:118)
	at org.testng.Assert.assertEquals(Assert.java:365)
	at org.testng.Assert.assertEquals(Assert.java:375)
	at MavenTestCases.TestClass1.Test1(TestClass1.java:13)
	at sun.reflect.NativeMethodAccessorImpl.invoke0(Native Method)
	at sun.reflect.NativeMethodAccessorImpl.invoke(NativeMethodAccessorImpl.java:62)
	at sun.reflect.DelegatingMethodAccessorImpl.invoke(DelegatingMethodAccessorImpl.java:43)
	at java.lang.reflect.Method.invoke(Method.java:497)
	at org.testng.internal.MethodInvocationHelper.invokeMethod(MethodInvocationHelper.java:80)
	at org.testng.internal.Invoker.invokeMethod(Invoker.java:702)
	at org.testng.internal.Invoker.invokeTestMethod(Invoker.java:894)
	at org.testng.internal.Invoker.invokeTestMethods(Invoker.java:1219)
	at org.testng.internal.TestMethodWorker.invokeTestMethods(TestMethodWorker.java:127)
	at org.testng.internal.TestMethodWorker.run(TestMethodWorker.java:111)
	at org.testng.TestRunner.privateRun(TestRunner.java:768)
	at org.testng.TestRunner.run(TestRunner.java:617)
	at org.testng.SuiteRunner.runTest(SuiteRunner.java:334)
	at org.testng.SuiteRunner.runSequentially(SuiteRunner.java:329)
	at org.testng.SuiteRunner.privateRun(SuiteRunner.java:291)
	at org.testng.SuiteRunner.run(SuiteRunner.java:240)
	at org.testng.SuiteRunnerWorker.runSuite(SuiteRunnerWorker.java:53)
	at org.testng.SuiteRunnerWorker.run(SuiteRunnerWorker.java:87)
	at org.testng.TestNG.runSuitesSequentially(TestNG.java:1188)
	at org.testng.TestNG.runSuitesLocally(TestNG.java:1113)
	at org.testng.TestNG.run(TestNG.java:1025)
	at org.apache.maven.surefire.testng.TestNGExecutor.run(TestNGExecutor.java:282)
	at org.apache.maven.surefire.testng.TestNGXmlTestSuite.execute(TestNGXmlTestSuite.java:83)
	at org.apache.maven.surefire.testng.TestNGProvider.invoke(TestNGProvider.java:114)
	at org.apache.maven.surefire.booter.ForkedBooter.invokeProviderInSameClassLoader(ForkedBooter.java:286)
	at org.apache.maven.surefire.booter.ForkedBooter.runSuitesInProcess(ForkedBooter.java:240)
	at org.apache.maven.surefire.booter.ForkedBooter.main(ForkedBooter.java:121)
]]>
            </full-stacktrace>
          </exception> <!-- java.lang.AssertionError -->
        </test-method> <!-- Test1 -->
        <test-method status="PASS" signature="Test2()[pri:0, instance:MavenTestCases.TestClass1@735f7ae5]" name="Test2" duration-ms="0" started-at="2015-11-27T16:56:34Z" finished-at="2015-11-27T16:56:34Z">
        </test-method> <!-- Test2 -->
        <test-method status="PASS" signature="Test3()[pri:0, instance:MavenTestCases.TestClass1@735f7ae5]" name="Test3" duration-ms="0" started-at="2015-11-27T16:56:34Z" finished-at="2015-11-27T16:56:34Z">
        </test-method> <!-- Test3 -->
        <test-method status="FAIL" signature="Test4()[pri:0, instance:MavenTestCases.TestClass1@735f7ae5]" name="Test4" duration-ms="0" started-at="2015-11-27T16:56:34Z" finished-at="2015-11-27T16:56:34Z">
          <exception class="java.lang.AssertionError">
            <message>
              <![CDATA[expected:<20> but was:<15>]]>
            </message>
            <full-stacktrace>
              <![CDATA[java.lang.AssertionError: expected:<20> but was:<15>
	at org.testng.Assert.fail(Assert.java:89)
	at org.testng.Assert.failNotEquals(Assert.java:489)
	at org.testng.Assert.assertEquals(Assert.java:118)
	at org.testng.Assert.assertEquals(Assert.java:365)
	at org.testng.Assert.assertEquals(Assert.java:375)
	at MavenTestCases.TestClass1.Test4(TestClass1.java:31)
	at sun.reflect.NativeMethodAccessorImpl.invoke0(Native Method)
	at sun.reflect.NativeMethodAccessorImpl.invoke(NativeMethodAccessorImpl.java:62)
	at sun.reflect.DelegatingMethodAccessorImpl.invoke(DelegatingMethodAccessorImpl.java:43)
	at java.lang.reflect.Method.invoke(Method.java:497)
	at org.testng.internal.MethodInvocationHelper.invokeMethod(MethodInvocationHelper.java:80)
	at org.testng.internal.Invoker.invokeMethod(Invoker.java:702)
	at org.testng.internal.Invoker.invokeTestMethod(Invoker.java:894)
	at org.testng.internal.Invoker.invokeTestMethods(Invoker.java:1219)
	at org.testng.internal.TestMethodWorker.invokeTestMethods(TestMethodWorker.java:127)
	at org.testng.internal.TestMethodWorker.run(TestMethodWorker.java:111)
	at org.testng.TestRunner.privateRun(TestRunner.java:768)
	at org.testng.TestRunner.run(TestRunner.java:617)
	at org.testng.SuiteRunner.runTest(SuiteRunner.java:334)
	at org.testng.SuiteRunner.runSequentially(SuiteRunner.java:329)
	at org.testng.SuiteRunner.privateRun(SuiteRunner.java:291)
	at org.testng.SuiteRunner.run(SuiteRunner.java:240)
	at org.testng.SuiteRunnerWorker.runSuite(SuiteRunnerWorker.java:53)
	at org.testng.SuiteRunnerWorker.run(SuiteRunnerWorker.java:87)
	at org.testng.TestNG.runSuitesSequentially(TestNG.java:1188)
	at org.testng.TestNG.runSuitesLocally(TestNG.java:1113)
	at org.testng.TestNG.run(TestNG.java:1025)
	at org.apache.maven.surefire.testng.TestNGExecutor.run(TestNGExecutor.java:282)
	at org.apache.maven.surefire.testng.TestNGXmlTestSuite.execute(TestNGXmlTestSuite.java:83)
	at org.apache.maven.surefire.testng.TestNGProvider.invoke(TestNGProvider.java:114)
	at org.apache.maven.surefire.booter.ForkedBooter.invokeProviderInSameClassLoader(ForkedBooter.java:286)
	at org.apache.maven.surefire.booter.ForkedBooter.runSuitesInProcess(ForkedBooter.java:240)
	at org.apache.maven.surefire.booter.ForkedBooter.main(ForkedBooter.java:121)
]]>
            </full-stacktrace>
          </exception> <!-- java.lang.AssertionError -->
        </test-method> <!-- Test4 -->
        <test-method status="FAIL" signature="Test5()[pri:0, instance:MavenTestCases.TestClass1@735f7ae5]" name="Test5" duration-ms="0" started-at="2015-11-27T16:56:34Z" finished-at="2015-11-27T16:56:34Z">
          <exception class="java.lang.AssertionError">
            <message>
              <![CDATA[expected:<20> but was:<15>]]>
            </message>
            <full-stacktrace>
              <![CDATA[java.lang.AssertionError: expected:<20> but was:<15>
	at org.testng.Assert.fail(Assert.java:89)
	at org.testng.Assert.failNotEquals(Assert.java:489)
	at org.testng.Assert.assertEquals(Assert.java:118)
	at org.testng.Assert.assertEquals(Assert.java:365)
	at org.testng.Assert.assertEquals(Assert.java:375)
	at MavenTestCases.TestClass1.Test5(TestClass1.java:37)
	at sun.reflect.NativeMethodAccessorImpl.invoke0(Native Method)
	at sun.reflect.NativeMethodAccessorImpl.invoke(NativeMethodAccessorImpl.java:62)
	at sun.reflect.DelegatingMethodAccessorImpl.invoke(DelegatingMethodAccessorImpl.java:43)
	at java.lang.reflect.Method.invoke(Method.java:497)
	at org.testng.internal.MethodInvocationHelper.invokeMethod(MethodInvocationHelper.java:80)
	at org.testng.internal.Invoker.invokeMethod(Invoker.java:702)
	at org.testng.internal.Invoker.invokeTestMethod(Invoker.java:894)
	at org.testng.internal.Invoker.invokeTestMethods(Invoker.java:1219)
	at org.testng.internal.TestMethodWorker.invokeTestMethods(TestMethodWorker.java:127)
	at org.testng.internal.TestMethodWorker.run(TestMethodWorker.java:111)
	at org.testng.TestRunner.privateRun(TestRunner.java:768)
	at org.testng.TestRunner.run(TestRunner.java:617)
	at org.testng.SuiteRunner.runTest(SuiteRunner.java:334)
	at org.testng.SuiteRunner.runSequentially(SuiteRunner.java:329)
	at org.testng.SuiteRunner.privateRun(SuiteRunner.java:291)
	at org.testng.SuiteRunner.run(SuiteRunner.java:240)
	at org.testng.SuiteRunnerWorker.runSuite(SuiteRunnerWorker.java:53)
	at org.testng.SuiteRunnerWorker.run(SuiteRunnerWorker.java:87)
	at org.testng.TestNG.runSuitesSequentially(TestNG.java:1188)
	at org.testng.TestNG.runSuitesLocally(TestNG.java:1113)
	at org.testng.TestNG.run(TestNG.java:1025)
	at org.apache.maven.surefire.testng.TestNGExecutor.run(TestNGExecutor.java:282)
	at org.apache.maven.surefire.testng.TestNGXmlTestSuite.execute(TestNGXmlTestSuite.java:83)
	at org.apache.maven.surefire.testng.TestNGProvider.invoke(TestNGProvider.java:114)
	at org.apache.maven.surefire.booter.ForkedBooter.invokeProviderInSameClassLoader(ForkedBooter.java:286)
	at org.apache.maven.surefire.booter.ForkedBooter.runSuitesInProcess(ForkedBooter.java:240)
	at org.apache.maven.surefire.booter.ForkedBooter.main(ForkedBooter.java:121)
]]>
            </full-stacktrace>
          </exception> <!-- java.lang.AssertionError -->
        </test-method> <!-- Test5 -->
      </class> <!-- MavenTestCases.TestClass1 -->
      <class name="MavenTestCases.TestClass2">
        <test-method status="PASS" signature="MyTestThree()[pri:0, instance:MavenTestCases.TestClass2@4e04a765]" name="MyTestThree" duration-ms="11" started-at="2015-11-27T16:56:34Z" finished-at="2015-11-27T16:56:34Z">
        </test-method> <!-- MyTestThree -->
      </class> <!-- MavenTestCases.TestClass2 -->
    </test> <!-- Test -->
  </suite> <!-- Suite -->
</testng-results>
